[2025-01-29T01:21:32.758+0000] {taskinstance.py:1103} INFO - Dependencies all met for dep_context=non-requeueable deps ti=<TaskInstance: data_pipeline_dag.process_csv_files manual__2025-01-29T01:16:25.737551+00:00 [queued]>
[2025-01-29T01:21:32.774+0000] {taskinstance.py:1103} INFO - Dependencies all met for dep_context=requeueable deps ti=<TaskInstance: data_pipeline_dag.process_csv_files manual__2025-01-29T01:16:25.737551+00:00 [queued]>
[2025-01-29T01:21:32.775+0000] {taskinstance.py:1308} INFO - Starting attempt 2 of 2
[2025-01-29T01:21:32.801+0000] {taskinstance.py:1327} INFO - Executing <Task(PythonOperator): process_csv_files> on 2025-01-29 01:16:25.737551+00:00
[2025-01-29T01:21:32.811+0000] {standard_task_runner.py:57} INFO - Started process 307 to run task
[2025-01-29T01:21:32.818+0000] {standard_task_runner.py:84} INFO - Running: ['airflow', 'tasks', 'run', 'data_pipeline_dag', 'process_csv_files', 'manual__2025-01-29T01:16:25.737551+00:00', '--job-id', '5', '--raw', '--subdir', 'DAGS_FOLDER/data_pipeline_dag.py', '--cfg-path', '/tmp/tmp7mc_lk9z']
[2025-01-29T01:21:32.824+0000] {standard_task_runner.py:85} INFO - Job 5: Subtask process_csv_files
[2025-01-29T01:21:32.930+0000] {task_command.py:410} INFO - Running <TaskInstance: data_pipeline_dag.process_csv_files manual__2025-01-29T01:16:25.737551+00:00 [running]> on host bbe8f3f0f995
[2025-01-29T01:21:33.125+0000] {taskinstance.py:1547} INFO - Exporting env vars: AIRFLOW_CTX_DAG_OWNER='airflow' AIRFLOW_CTX_DAG_ID='data_pipeline_dag' AIRFLOW_CTX_TASK_ID='process_csv_files' AIRFLOW_CTX_EXECUTION_DATE='2025-01-29T01:16:25.737551+00:00' AIRFLOW_CTX_TRY_NUMBER='2' AIRFLOW_CTX_DAG_RUN_ID='manual__2025-01-29T01:16:25.737551+00:00'
[2025-01-29T01:21:33.276+0000] {taskinstance.py:1824} ERROR - Task failed with exception
Traceback (most recent call last):
  File "/home/airflow/.local/lib/python3.7/site-packages/airflow/operators/python.py", line 181, in execute
    return_value = self.execute_callable()
  File "/home/airflow/.local/lib/python3.7/site-packages/airflow/operators/python.py", line 198, in execute_callable
    return self.python_callable(*self.op_args, **self.op_kwargs)
  File "/opt/airflow/dags/../scripts/main.py", line 34, in process_csv
    (row["timestamp"], row["price"], row["user_id"]),
psycopg2.errors.UndefinedTable: relation "transactions" does not exist
LINE 1: INSERT INTO transactions (timestamp, price, user_id) VALUES ...
                    ^

[2025-01-29T01:21:33.299+0000] {taskinstance.py:1350} INFO - Marking task as FAILED. dag_id=data_pipeline_dag, task_id=process_csv_files, execution_date=20250129T011625, start_date=20250129T012132, end_date=20250129T012133
[2025-01-29T01:21:33.335+0000] {standard_task_runner.py:109} ERROR - Failed to execute job 5 for task process_csv_files (relation "transactions" does not exist
LINE 1: INSERT INTO transactions (timestamp, price, user_id) VALUES ...
                    ^
; 307)
[2025-01-29T01:21:33.354+0000] {local_task_job_runner.py:225} INFO - Task exited with return code 1
[2025-01-29T01:21:33.404+0000] {taskinstance.py:2653} INFO - 0 downstream tasks scheduled from follow-on schedule check
